<sdf version='1.7'>
  <world name='default'>
    <light name='sun' type='directional'>
      <cast_shadows>1</cast_shadows>
      <pose>0 0 10 0 -0 0</pose>
      <diffuse>0.8 0.8 0.8 1</diffuse>
      <specular>0.2 0.2 0.2 1</specular>
      <attenuation>
        <range>1000</range>
        <constant>0.9</constant>
        <linear>0.01</linear>
        <quadratic>0.001</quadratic>
      </attenuation>
      <direction>-0.5 0.1 -0.9</direction>
      <spot>
        <inner_angle>0</inner_angle>
        <outer_angle>0</outer_angle>
        <falloff>0</falloff>
      </spot>
    </light>
    <model name='ground_plane'>
      <static>1</static>
      <link name='link'>
        <collision name='collision'>
          <geometry>
            <plane>
              <normal>0 0 1</normal>
              <size>100 100</size>
            </plane>
          </geometry>
          <surface>
            <friction>
              <ode>
                <mu>100</mu>
                <mu2>50</mu2>
              </ode>
              <torsional>
                <ode/>
              </torsional>
            </friction>
            <contact>
              <ode/>
            </contact>
            <bounce/>
          </surface>
          <max_contacts>10</max_contacts>
        </collision>
        <visual name='visual'>
          <cast_shadows>0</cast_shadows>
          <geometry>
            <plane>
              <normal>0 0 1</normal>
              <size>100 100</size>
            </plane>
          </geometry>
          <material>
            <script>
              <uri>file://media/materials/scripts/gazebo.material</uri>
              <name>Gazebo/Grey</name>
            </script>
          </material>
        </visual>
        <self_collide>0</self_collide>
        <enable_wind>0</enable_wind>
        <kinematic>0</kinematic>
      </link>
    </model>
    <gravity>0 0 -9.8</gravity>
    <magnetic_field>6e-06 2.3e-05 -4.2e-05</magnetic_field>
    <atmosphere type='adiabatic'/>
    <physics type='ode'>
      <max_step_size>0.001</max_step_size>
      <real_time_factor>1</real_time_factor>
      <real_time_update_rate>1000</real_time_update_rate>
    </physics>
    <scene>
      <ambient>0.4 0.4 0.4 1</ambient>
      <background>0.7 0.7 0.7 1</background>
      <shadows>1</shadows>
    </scene>
    <wind/>
    <spherical_coordinates>
      <surface_model>EARTH_WGS84</surface_model>
      <latitude_deg>0</latitude_deg>
      <longitude_deg>0</longitude_deg>
      <elevation>0</elevation>
      <heading_deg>0</heading_deg>
    </spherical_coordinates>
    <model name='drone'>
      <model name='house'>
        <pose>1.71681 0.000122 0 0 -0 0</pose>
        <link name='Wall_0'>
          <collision name='Wall_0_Collision'>
            <geometry>
              <box>
                <size>3 0.15 2.5</size>
              </box>
            </geometry>
            <pose>0 0 1.25 0 -0 0</pose>
            <max_contacts>10</max_contacts>
            <surface>
              <contact>
                <ode/>
              </contact>
              <bounce/>
              <friction>
                <torsional>
                  <ode/>
                </torsional>
                <ode/>
              </friction>
            </surface>
          </collision>
          <visual name='Wall_0_Visual'>
            <pose>0 0 1.25 0 -0 0</pose>
            <geometry>
              <box>
                <size>3 0.15 2.5</size>
              </box>
            </geometry>
            <material>
              <script>
                <uri>file://media/materials/scripts/gazebo.material</uri>
                <name>Gazebo/Grey</name>
              </script>
              <ambient>1 1 1 1</ambient>
            </material>
            <meta>
              <layer>0</layer>
            </meta>
          </visual>
          <pose>-6.03 -0.2725 0 0 -0 -1.5708</pose>
          <self_collide>0</self_collide>
          <enable_wind>0</enable_wind>
          <kinematic>0</kinematic>
        </link>
        <link name='Wall_1'>
          <collision name='Wall_1_Collision'>
            <geometry>
              <box>
                <size>4.25 0.15 2.5</size>
              </box>
            </geometry>
            <pose>0 0 1.25 0 -0 0</pose>
            <max_contacts>10</max_contacts>
            <surface>
              <contact>
                <ode/>
              </contact>
              <bounce/>
              <friction>
                <torsional>
                  <ode/>
                </torsional>
                <ode/>
              </friction>
            </surface>
          </collision>
          <visual name='Wall_1_Visual'>
            <pose>0 0 1.25 0 -0 0</pose>
            <geometry>
              <box>
                <size>4.25 0.15 2.5</size>
              </box>
            </geometry>
            <material>
              <script>
                <uri>file://media/materials/scripts/gazebo.material</uri>
                <name>Gazebo/Grey</name>
              </script>
              <ambient>1 1 1 1</ambient>
            </material>
            <meta>
              <layer>0</layer>
            </meta>
          </visual>
          <pose>-3.98 -1.6975 0 0 -0 0</pose>
          <self_collide>0</self_collide>
          <enable_wind>0</enable_wind>
          <kinematic>0</kinematic>
        </link>
        <link name='Wall_10'>
          <collision name='Wall_10_Collision'>
            <geometry>
              <box>
                <size>3.5 0.15 2.5</size>
              </box>
            </geometry>
            <pose>0 0 1.25 0 -0 0</pose>
            <max_contacts>10</max_contacts>
            <surface>
              <contact>
                <ode/>
              </contact>
              <bounce/>
              <friction>
                <torsional>
                  <ode/>
                </torsional>
                <ode/>
              </friction>
            </surface>
          </collision>
          <visual name='Wall_10_Visual'>
            <pose>0 0 1.25 0 -0 0</pose>
            <geometry>
              <box>
                <size>3.5 0.15 2.5</size>
              </box>
            </geometry>
            <material>
              <script>
                <uri>file://media/materials/scripts/gazebo.material</uri>
                <name>Gazebo/Grey</name>
              </script>
              <ambient>1 1 1 1</ambient>
            </material>
            <meta>
              <layer>0</layer>
            </meta>
          </visual>
          <pose>-0.255 -1.6975 0 0 -0 0</pose>
          <self_collide>0</self_collide>
          <enable_wind>0</enable_wind>
          <kinematic>0</kinematic>
        </link>
        <link name='Wall_11'>
          <collision name='Wall_11_Collision'>
            <geometry>
              <box>
                <size>0.16 0.15 2.5</size>
              </box>
            </geometry>
            <pose>0 0 1.25 0 -0 0</pose>
            <max_contacts>10</max_contacts>
            <surface>
              <contact>
                <ode/>
              </contact>
              <bounce/>
              <friction>
                <torsional>
                  <ode/>
                </torsional>
                <ode/>
              </friction>
            </surface>
          </collision>
          <visual name='Wall_11_Visual'>
            <pose>0 0 1.25 0 -0 0</pose>
            <geometry>
              <box>
                <size>0.16 0.15 2.5</size>
              </box>
            </geometry>
            <material>
              <script>
                <uri>file://media/materials/scripts/gazebo.material</uri>
                <name>Gazebo/Grey</name>
              </script>
              <ambient>1 1 1 1</ambient>
            </material>
            <meta>
              <layer>0</layer>
            </meta>
          </visual>
          <pose>1.425 -1.6975 0 0 -0 0</pose>
          <self_collide>0</self_collide>
          <enable_wind>0</enable_wind>
          <kinematic>0</kinematic>
        </link>
        <link name='Wall_12'>
          <collision name='Wall_12_Collision'>
            <geometry>
              <box>
                <size>4.75 0.15 2.5</size>
              </box>
            </geometry>
            <pose>0 0 1.25 0 -0 0</pose>
            <max_contacts>10</max_contacts>
            <surface>
              <contact>
                <ode/>
              </contact>
              <bounce/>
              <friction>
                <torsional>
                  <ode/>
                </torsional>
                <ode/>
              </friction>
            </surface>
          </collision>
          <visual name='Wall_12_Visual'>
            <pose>0 0 1.25 0 -0 0</pose>
            <geometry>
              <box>
                <size>4.75 0.15 2.5</size>
              </box>
            </geometry>
            <material>
              <script>
                <uri>file://media/materials/scripts/gazebo.material</uri>
                <name>Gazebo/Grey</name>
              </script>
              <ambient>1 1 1 1</ambient>
            </material>
            <meta>
              <layer>0</layer>
            </meta>
          </visual>
          <pose>3.73 -1.6975 0 0 -0 0</pose>
          <self_collide>0</self_collide>
          <enable_wind>0</enable_wind>
          <kinematic>0</kinematic>
        </link>
        <link name='Wall_13'>
          <collision name='Wall_13_Collision'>
            <geometry>
              <box>
                <size>2.25 0.15 2.5</size>
              </box>
            </geometry>
            <pose>0 0 1.25 0 -0 0</pose>
            <max_contacts>10</max_contacts>
            <surface>
              <contact>
                <ode/>
              </contact>
              <bounce/>
              <friction>
                <torsional>
                  <ode/>
                </torsional>
                <ode/>
              </friction>
            </surface>
          </collision>
          <visual name='Wall_13_Visual'>
            <pose>0 0 1.25 0 -0 0</pose>
            <geometry>
              <box>
                <size>2.25 0.15 2.5</size>
              </box>
            </geometry>
            <material>
              <script>
                <uri>file://media/materials/scripts/gazebo.material</uri>
                <name>Gazebo/Grey</name>
              </script>
              <ambient>1 1 1 1</ambient>
            </material>
            <meta>
              <layer>0</layer>
            </meta>
          </visual>
          <pose>6.03 -0.6475 0 0 -0 1.5708</pose>
          <self_collide>0</self_collide>
          <enable_wind>0</enable_wind>
          <kinematic>0</kinematic>
        </link>
        <link name='Wall_15'>
          <collision name='Wall_15_Collision'>
            <geometry>
              <box>
                <size>4.75 0.15 2.5</size>
              </box>
            </geometry>
            <pose>0 0 1.25 0 -0 0</pose>
            <max_contacts>10</max_contacts>
            <surface>
              <contact>
                <ode/>
              </contact>
              <bounce/>
              <friction>
                <torsional>
                  <ode/>
                </torsional>
                <ode/>
              </friction>
            </surface>
          </collision>
          <visual name='Wall_15_Visual'>
            <pose>0 0 1.25 0 -0 0</pose>
            <geometry>
              <box>
                <size>4.75 0.15 2.5</size>
              </box>
            </geometry>
            <material>
              <script>
                <uri>file://media/materials/scripts/gazebo.material</uri>
                <name>Gazebo/Grey</name>
              </script>
              <ambient>1 1 1 1</ambient>
            </material>
            <meta>
              <layer>0</layer>
            </meta>
          </visual>
          <pose>3.72 1.1525 0 0 -0 0</pose>
          <self_collide>0</self_collide>
          <enable_wind>0</enable_wind>
          <kinematic>0</kinematic>
        </link>
        <link name='Wall_2'>
          <collision name='Wall_2_Collision'>
            <geometry>
              <box>
                <size>1 0.15 2.5</size>
              </box>
            </geometry>
            <pose>0 0 1.25 0 -0 0</pose>
            <max_contacts>10</max_contacts>
            <surface>
              <contact>
                <ode/>
              </contact>
              <bounce/>
              <friction>
                <torsional>
                  <ode/>
                </torsional>
                <ode/>
              </friction>
            </surface>
          </collision>
          <visual name='Wall_2_Visual'>
            <pose>0 0 1.25 0 -0 0</pose>
            <geometry>
              <box>
                <size>1 0.15 2.5</size>
              </box>
            </geometry>
            <material>
              <script>
                <uri>file://media/materials/scripts/gazebo.material</uri>
                <name>Gazebo/Grey</name>
              </script>
              <ambient>1 1 1 1</ambient>
            </material>
            <meta>
              <layer>0</layer>
            </meta>
          </visual>
          <pose>-1.93 -1.2725 0 0 -0 1.5708</pose>
          <self_collide>0</self_collide>
          <enable_wind>0</enable_wind>
          <kinematic>0</kinematic>
        </link>
        <link name='Wall_4'>
          <collision name='Wall_4_Collision'>
            <geometry>
              <box>
                <size>4.25 0.15 2.5</size>
              </box>
            </geometry>
            <pose>0 0 1.25 0 -0 0</pose>
            <max_contacts>10</max_contacts>
            <surface>
              <contact>
                <ode/>
              </contact>
              <bounce/>
              <friction>
                <torsional>
                  <ode/>
                </torsional>
                <ode/>
              </friction>
            </surface>
          </collision>
          <visual name='Wall_4_Visual'>
            <pose>0 0 1.25 0 -0 0</pose>
            <geometry>
              <box>
                <size>4.25 0.15 2.5</size>
              </box>
            </geometry>
            <material>
              <script>
                <uri>file://media/materials/scripts/gazebo.material</uri>
                <name>Gazebo/Grey</name>
              </script>
              <ambient>1 1 1 1</ambient>
            </material>
            <meta>
              <layer>0</layer>
            </meta>
          </visual>
          <pose>-3.98 1.1525 0 0 -0 0</pose>
          <self_collide>0</self_collide>
          <enable_wind>0</enable_wind>
          <kinematic>0</kinematic>
        </link>
        <link name='Wall_5'>
          <collision name='Wall_5_Collision'>
            <geometry>
              <box>
                <size>1 0.15 2.5</size>
              </box>
            </geometry>
            <pose>0 0 1.25 0 -0 0</pose>
            <max_contacts>10</max_contacts>
            <surface>
              <contact>
                <ode/>
              </contact>
              <bounce/>
              <friction>
                <torsional>
                  <ode/>
                </torsional>
                <ode/>
              </friction>
            </surface>
          </collision>
          <visual name='Wall_5_Visual'>
            <pose>0 0 1.25 0 -0 0</pose>
            <geometry>
              <box>
                <size>1 0.15 2.5</size>
              </box>
            </geometry>
            <material>
              <script>
                <uri>file://media/materials/scripts/gazebo.material</uri>
                <name>Gazebo/Grey</name>
              </script>
              <ambient>1 1 1 1</ambient>
            </material>
            <meta>
              <layer>0</layer>
            </meta>
          </visual>
          <pose>-1.93 0.7275 0 0 -0 -1.5708</pose>
          <self_collide>0</self_collide>
          <enable_wind>0</enable_wind>
          <kinematic>0</kinematic>
        </link>
        <link name='Wall_7'>
          <collision name='Wall_7_Collision'>
            <geometry>
              <box>
                <size>3.5 0.15 2.5</size>
              </box>
            </geometry>
            <pose>0 0 1.25 0 -0 0</pose>
            <max_contacts>10</max_contacts>
            <surface>
              <contact>
                <ode/>
              </contact>
              <bounce/>
              <friction>
                <torsional>
                  <ode/>
                </torsional>
                <ode/>
              </friction>
            </surface>
          </collision>
          <visual name='Wall_7_Visual'>
            <pose>0 0 1.25 0 -0 0</pose>
            <geometry>
              <box>
                <size>3.5 0.15 2.5</size>
              </box>
            </geometry>
            <material>
              <script>
                <uri>file://media/materials/scripts/gazebo.material</uri>
                <name>Gazebo/Grey</name>
              </script>
              <ambient>1 1 1 1</ambient>
            </material>
            <meta>
              <layer>0</layer>
            </meta>
          </visual>
          <pose>-0.255 1.1525 0 0 -0 0</pose>
          <self_collide>0</self_collide>
          <enable_wind>0</enable_wind>
          <kinematic>0</kinematic>
        </link>
        <link name='Wall_8'>
          <collision name='Wall_8_Collision'>
            <geometry>
              <box>
                <size>2.25 0.15 2.5</size>
              </box>
            </geometry>
            <pose>0 0 1.25 0 -0 0</pose>
            <max_contacts>10</max_contacts>
            <surface>
              <contact>
                <ode/>
              </contact>
              <bounce/>
              <friction>
                <torsional>
                  <ode/>
                </torsional>
                <ode/>
              </friction>
            </surface>
          </collision>
          <visual name='Wall_8_Visual'>
            <pose>0 0 1.25 0 -0 0</pose>
            <geometry>
              <box>
                <size>2.25 0.15 2.5</size>
              </box>
            </geometry>
            <material>
              <script>
                <uri>file://media/materials/scripts/gazebo.material</uri>
                <name>Gazebo/Grey</name>
              </script>
              <ambient>1 1 1 1</ambient>
            </material>
            <meta>
              <layer>0</layer>
            </meta>
          </visual>
          <pose>1.42 0.1025 0 0 -0 -1.5708</pose>
          <self_collide>0</self_collide>
          <enable_wind>0</enable_wind>
          <kinematic>0</kinematic>
        </link>
        <static>1</static>
      </model>
      <model name='iris_demo'>
        <frame name='iris::__model__' attached_to='iris::base_link'>
          <pose relative_to='__model__'>0 0 0.194923 0 -0 0</pose>
        </frame>
        <link name='iris::base_link'>
          <velocity_decay>
            <linear>0</linear>
            <angular>0</angular>
          </velocity_decay>
          <inertial>
            <pose>0 0 0 0 -0 0</pose>
            <mass>1.5</mass>
            <inertia>
              <ixx>0.008</ixx>
              <ixy>0</ixy>
              <ixz>0</ixz>
              <iyy>0.015</iyy>
              <iyz>0</iyz>
              <izz>0.017</izz>
            </inertia>
          </inertial>
          <collision name='base_link_collision'>
            <pose>0 0 -0.08 0 -0 0</pose>
            <geometry>
              <box>
                <size>0.47 0.47 0.23</size>
              </box>
            </geometry>
            <surface>
              <contact>
                <ode>
                  <max_vel>100</max_vel>
                  <min_depth>0.001</min_depth>
                </ode>
              </contact>
              <friction>
                <ode>
                  <mu>1</mu>
                  <mu2>1</mu2>
                </ode>
                <torsional>
                  <ode/>
                </torsional>
              </friction>
              <bounce/>
            </surface>
            <max_contacts>10</max_contacts>
          </collision>
          <visual name='base_link_visual'>
            <geometry>
              <mesh>
                <uri>model://iris_with_standoffs/meshes/iris.dae</uri>
              </mesh>
            </geometry>
            <material>
              <script>
                <name>Gazebo/DarkGrey</name>
                <uri>__default__</uri>
              </script>
            </material>
          </visual>
          <visual name='front_left_leg_visual'>
            <pose>0.123 0.22 -0.11 0 -0 0</pose>
            <geometry>
              <cylinder>
                <radius>0.005</radius>
                <length>0.17</length>
              </cylinder>
            </geometry>
            <material>
              <script>
                <name>Gazebo/FlatBlack</name>
                <uri>file://media/materials/scripts/gazebo.material</uri>
              </script>
            </material>
          </visual>
          <visual name='front_right_leg_visual'>
            <pose>0.123 -0.22 -0.11 0 -0 0</pose>
            <geometry>
              <cylinder>
                <radius>0.005</radius>
                <length>0.17</length>
              </cylinder>
            </geometry>
            <material>
              <script>
                <name>Gazebo/FlatBlack</name>
                <uri>file://media/materials/scripts/gazebo.material</uri>
              </script>
            </material>
          </visual>
          <visual name='rear_left_leg_visual'>
            <pose>-0.14 0.21 -0.11 0 -0 0</pose>
            <geometry>
              <cylinder>
                <radius>0.005</radius>
                <length>0.17</length>
              </cylinder>
            </geometry>
            <material>
              <script>
                <name>Gazebo/FlatBlack</name>
                <uri>file://media/materials/scripts/gazebo.material</uri>
              </script>
            </material>
          </visual>
          <visual name='rear_right_leg_visual'>
            <pose>-0.14 -0.21 -0.11 0 -0 0</pose>
            <geometry>
              <cylinder>
                <radius>0.005</radius>
                <length>0.17</length>
              </cylinder>
            </geometry>
            <material>
              <script>
                <name>Gazebo/FlatBlack</name>
                <uri>file://media/materials/scripts/gazebo.material</uri>
              </script>
            </material>
          </visual>
          <pose>0 0 0.194923 0 -0 0</pose>
          <self_collide>0</self_collide>
          <enable_wind>0</enable_wind>
          <kinematic>0</kinematic>
        </link>
        <link name='iris::iris/ground_truth/odometry_sensorgt_link'>
          <pose>0 0 0.194923 0 -0 0</pose>
          <inertial>
            <pose>0 0 0 0 -0 0</pose>
            <mass>0.15</mass>
            <inertia>
              <ixx>0.0001</ixx>
              <ixy>0</ixy>
              <ixz>0</ixz>
              <iyy>0.0002</iyy>
              <iyz>0</iyz>
              <izz>0.0002</izz>
            </inertia>
          </inertial>
          <self_collide>0</self_collide>
          <enable_wind>0</enable_wind>
          <kinematic>0</kinematic>
        </link>
        <joint name='iris::iris/ground_truth/odometry_sensorgt_joint' type='revolute'>
          <child>iris::iris/ground_truth/odometry_sensorgt_link</child>
          <parent>iris::base_link</parent>
          <axis>
            <xyz>0 0 1</xyz>
            <limit>
              <lower>0</lower>
              <upper>0</upper>
              <effort>0</effort>
              <velocity>0</velocity>
            </limit>
            <dynamics>
              <damping>1</damping>
              <spring_reference>0</spring_reference>
              <spring_stiffness>0</spring_stiffness>
            </dynamics>
          </axis>
          <physics>
            <ode>
              <implicit_spring_damper>1</implicit_spring_damper>
              <limit>
                <cfm>0</cfm>
                <erp>0.2</erp>
              </limit>
            </ode>
          </physics>
        </joint>
        <link name='iris::iris/imu_link'>
          <inertial>
            <pose>0 0 0 0 -0 0</pose>
            <mass>0.15</mass>
            <inertia>
              <ixx>1e-05</ixx>
              <ixy>0</ixy>
              <ixz>0</ixz>
              <iyy>2e-05</iyy>
              <iyz>0</iyz>
              <izz>2e-05</izz>
            </inertia>
          </inertial>
          <sensor name='imu_sensor' type='imu'>
            <pose>0 0 0 -3.14159 -0 0</pose>
            <always_on>1</always_on>
            <update_rate>1000</update_rate>
            <imu/>
          </sensor>
          <pose>0 0 0.194923 0 -0 0</pose>
          <self_collide>0</self_collide>
          <enable_wind>0</enable_wind>
          <kinematic>0</kinematic>
        </link>
        <joint name='iris::iris/imu_joint' type='revolute'>
          <child>iris::iris/imu_link</child>
          <parent>iris::base_link</parent>
          <axis>
            <xyz>0 0 1</xyz>
            <limit>
              <lower>0</lower>
              <upper>0</upper>
              <effort>0</effort>
              <velocity>0</velocity>
            </limit>
            <dynamics>
              <damping>1</damping>
              <spring_reference>0</spring_reference>
              <spring_stiffness>0</spring_stiffness>
            </dynamics>
          </axis>
          <physics>
            <ode>
              <implicit_spring_damper>1</implicit_spring_damper>
              <limit>
                <cfm>0</cfm>
                <erp>0.2</erp>
              </limit>
            </ode>
          </physics>
        </joint>
        <link name='iris::rotor_0'>
          <pose>0.13 -0.22 0.217923 0 -0 0</pose>
          <inertial>
            <pose>0 0 0 0 -0 0</pose>
            <mass>0.025</mass>
            <inertia>
              <ixx>9.75e-06</ixx>
              <ixy>0</ixy>
              <ixz>0</ixz>
              <iyy>0.000166704</iyy>
              <iyz>0</iyz>
              <izz>0.000167604</izz>
            </inertia>
          </inertial>
          <collision name='rotor_0_collision'>
            <pose>0 0 0 0 -0 0</pose>
            <geometry>
              <cylinder>
                <length>0.005</length>
                <radius>0.1</radius>
              </cylinder>
            </geometry>
            <surface>
              <contact>
                <ode/>
              </contact>
              <friction>
                <ode/>
                <torsional>
                  <ode/>
                </torsional>
              </friction>
              <bounce/>
            </surface>
            <max_contacts>10</max_contacts>
          </collision>
          <visual name='rotor_0_visual'>
            <pose>0 0 0 0 -0 0</pose>
            <geometry>
              <mesh>
                <scale>1 1 1</scale>
                <uri>model://iris_with_standoffs/meshes/iris_prop_ccw.dae</uri>
              </mesh>
            </geometry>
            <material>
              <script>
                <name>Gazebo/Blue</name>
                <uri>__default__</uri>
              </script>
            </material>
          </visual>
          <gravity>1</gravity>
          <velocity_decay/>
          <self_collide>0</self_collide>
          <enable_wind>0</enable_wind>
          <kinematic>0</kinematic>
        </link>
        <joint name='iris::rotor_0_joint' type='revolute'>
          <child>iris::rotor_0</child>
          <parent>iris::base_link</parent>
          <axis>
            <xyz>0 0 1</xyz>
            <limit>
              <lower>-1e+16</lower>
              <upper>1e+16</upper>
            </limit>
            <dynamics>
              <damping>0.004</damping>
              <spring_reference>0</spring_reference>
              <spring_stiffness>0</spring_stiffness>
            </dynamics>
          </axis>
          <physics>
            <ode>
              <implicit_spring_damper>1</implicit_spring_damper>
              <limit>
                <cfm>0</cfm>
                <erp>0.2</erp>
              </limit>
            </ode>
          </physics>
        </joint>
        <link name='iris::rotor_1'>
          <pose>-0.13 0.2 0.217923 0 -0 0</pose>
          <inertial>
            <pose>0 0 0 0 -0 0</pose>
            <mass>0.025</mass>
            <inertia>
              <ixx>9.75e-06</ixx>
              <ixy>0</ixy>
              <ixz>0</ixz>
              <iyy>0.000166704</iyy>
              <iyz>0</iyz>
              <izz>0.000167604</izz>
            </inertia>
          </inertial>
          <collision name='rotor_1_collision'>
            <pose>0 0 0 0 -0 0</pose>
            <geometry>
              <cylinder>
                <length>0.005</length>
                <radius>0.1</radius>
              </cylinder>
            </geometry>
            <surface>
              <contact>
                <ode/>
              </contact>
              <friction>
                <ode/>
                <torsional>
                  <ode/>
                </torsional>
              </friction>
              <bounce/>
            </surface>
            <max_contacts>10</max_contacts>
          </collision>
          <visual name='rotor_1_visual'>
            <pose>0 0 0 0 -0 0</pose>
            <geometry>
              <mesh>
                <scale>1 1 1</scale>
                <uri>model://iris_with_standoffs/meshes/iris_prop_ccw.dae</uri>
              </mesh>
            </geometry>
            <material>
              <script>
                <name>Gazebo/DarkGrey</name>
                <uri>__default__</uri>
              </script>
            </material>
          </visual>
          <gravity>1</gravity>
          <velocity_decay/>
          <self_collide>0</self_collide>
          <enable_wind>0</enable_wind>
          <kinematic>0</kinematic>
        </link>
        <joint name='iris::rotor_1_joint' type='revolute'>
          <child>iris::rotor_1</child>
          <parent>iris::base_link</parent>
          <axis>
            <xyz>0 0 1</xyz>
            <limit>
              <lower>-1e+16</lower>
              <upper>1e+16</upper>
            </limit>
            <dynamics>
              <damping>0.004</damping>
              <spring_reference>0</spring_reference>
              <spring_stiffness>0</spring_stiffness>
            </dynamics>
          </axis>
          <physics>
            <ode>
              <implicit_spring_damper>1</implicit_spring_damper>
              <limit>
                <cfm>0</cfm>
                <erp>0.2</erp>
              </limit>
            </ode>
          </physics>
        </joint>
        <link name='iris::rotor_2'>
          <pose>0.13 0.22 0.217923 0 -0 0</pose>
          <inertial>
            <pose>0 0 0 0 -0 0</pose>
            <mass>0.025</mass>
            <inertia>
              <ixx>9.75e-06</ixx>
              <ixy>0</ixy>
              <ixz>0</ixz>
              <iyy>0.000166704</iyy>
              <iyz>0</iyz>
              <izz>0.000167604</izz>
            </inertia>
          </inertial>
          <collision name='rotor_2_collision'>
            <pose>0 0 0 0 -0 0</pose>
            <geometry>
              <cylinder>
                <length>0.005</length>
                <radius>0.1</radius>
              </cylinder>
            </geometry>
            <surface>
              <contact>
                <ode/>
              </contact>
              <friction>
                <ode/>
                <torsional>
                  <ode/>
                </torsional>
              </friction>
              <bounce/>
            </surface>
            <max_contacts>10</max_contacts>
          </collision>
          <visual name='rotor_2_visual'>
            <pose>0 0 0 0 -0 0</pose>
            <geometry>
              <mesh>
                <scale>1 1 1</scale>
                <uri>model://iris_with_standoffs/meshes/iris_prop_cw.dae</uri>
              </mesh>
            </geometry>
            <material>
              <script>
                <name>Gazebo/Blue</name>
                <uri>__default__</uri>
              </script>
            </material>
          </visual>
          <gravity>1</gravity>
          <velocity_decay/>
          <self_collide>0</self_collide>
          <enable_wind>0</enable_wind>
          <kinematic>0</kinematic>
        </link>
        <joint name='iris::rotor_2_joint' type='revolute'>
          <child>iris::rotor_2</child>
          <parent>iris::base_link</parent>
          <axis>
            <xyz>0 0 1</xyz>
            <limit>
              <lower>-1e+16</lower>
              <upper>1e+16</upper>
            </limit>
            <dynamics>
              <damping>0.004</damping>
              <spring_reference>0</spring_reference>
              <spring_stiffness>0</spring_stiffness>
            </dynamics>
          </axis>
          <physics>
            <ode>
              <implicit_spring_damper>1</implicit_spring_damper>
              <limit>
                <cfm>0</cfm>
                <erp>0.2</erp>
              </limit>
            </ode>
          </physics>
        </joint>
        <link name='iris::rotor_3'>
          <pose>-0.13 -0.2 0.217923 0 -0 0</pose>
          <inertial>
            <pose>0 0 0 0 -0 0</pose>
            <mass>0.025</mass>
            <inertia>
              <ixx>9.75e-06</ixx>
              <ixy>0</ixy>
              <ixz>0</ixz>
              <iyy>0.000166704</iyy>
              <iyz>0</iyz>
              <izz>0.000167604</izz>
            </inertia>
          </inertial>
          <collision name='rotor_3_collision'>
            <pose>0 0 0 0 -0 0</pose>
            <geometry>
              <cylinder>
                <length>0.005</length>
                <radius>0.1</radius>
              </cylinder>
            </geometry>
            <surface>
              <contact>
                <ode/>
              </contact>
              <friction>
                <ode/>
                <torsional>
                  <ode/>
                </torsional>
              </friction>
              <bounce/>
            </surface>
            <max_contacts>10</max_contacts>
          </collision>
          <visual name='rotor_3_visual'>
            <pose>0 0 0 0 -0 0</pose>
            <geometry>
              <mesh>
                <scale>1 1 1</scale>
                <uri>model://iris_with_standoffs/meshes/iris_prop_cw.dae</uri>
              </mesh>
            </geometry>
            <material>
              <script>
                <name>Gazebo/DarkGrey</name>
                <uri>__default__</uri>
              </script>
            </material>
          </visual>
          <gravity>1</gravity>
          <velocity_decay/>
          <self_collide>0</self_collide>
          <enable_wind>0</enable_wind>
          <kinematic>0</kinematic>
        </link>
        <joint name='iris::rotor_3_joint' type='revolute'>
          <child>iris::rotor_3</child>
          <parent>iris::base_link</parent>
          <axis>
            <xyz>0 0 1</xyz>
            <limit>
              <lower>-1e+16</lower>
              <upper>1e+16</upper>
            </limit>
            <dynamics>
              <damping>0.004</damping>
              <spring_reference>0</spring_reference>
              <spring_stiffness>0</spring_stiffness>
            </dynamics>
          </axis>
          <physics>
            <ode>
              <implicit_spring_damper>1</implicit_spring_damper>
              <limit>
                <cfm>0</cfm>
                <erp>0.2</erp>
              </limit>
            </ode>
          </physics>
        </joint>
        <static>0</static>
        <frame name='gimbal_small_2d::__model__' attached_to='gimbal_small_2d::base_link'>
          <pose relative_to='__model__'>0 -0.01 0.07 1.57 -0 1.57</pose>
        </frame>
        <link name='gimbal_small_2d::base_link'>
          <inertial>
            <mass>0.2</mass>
            <inertia>
              <ixx>0.0001</ixx>
              <ixy>0</ixy>
              <ixz>0</ixz>
              <iyy>0.0001</iyy>
              <iyz>0</iyz>
              <izz>0.0001</izz>
            </inertia>
            <pose>0 0 0 0 -0 0</pose>
          </inertial>
          <visual name='base_main_viz'>
            <geometry>
              <mesh>
                <scale>0.001 0.001 0.001</scale>
                <uri>model://gimbal_small_2d/meshes/base_main.dae</uri>
              </mesh>
            </geometry>
            <material>
              <script>
                <uri>file://media/materials/scripts/gazebo.material</uri>
                <name>Gazebo/FlatBlack</name>
              </script>
            </material>
          </visual>
          <visual name='base_arm_viz'>
            <geometry>
              <mesh>
                <scale>0.001 0.001 0.001</scale>
                <uri>model://gimbal_small_2d/meshes/base_arm.dae</uri>
              </mesh>
            </geometry>
            <material>
              <script>
                <uri>file://media/materials/scripts/gazebo.material</uri>
                <name>Gazebo/FlatBlack</name>
              </script>
            </material>
          </visual>
          <collision name='base_col'>
            <pose>0.01 0.075 -0.025 0 -0 0</pose>
            <geometry>
              <box>
                <size>0.1 0.05 0.15</size>
              </box>
            </geometry>
            <surface>
              <friction>
                <ode>
                  <mu>1</mu>
                  <mu2>1</mu2>
                  <fdir1>0 0 0</fdir1>
                  <slip1>0</slip1>
                  <slip2>0</slip2>
                </ode>
                <torsional>
                  <ode/>
                </torsional>
              </friction>
              <contact>
                <ode/>
              </contact>
              <bounce/>
            </surface>
            <max_contacts>10</max_contacts>
          </collision>
          <pose>0 -0.01 0.07 1.57 -0 1.57</pose>
          <self_collide>0</self_collide>
          <enable_wind>0</enable_wind>
          <kinematic>0</kinematic>
        </link>
        <link name='gimbal_small_2d::tilt_link'>
          <inertial>
            <mass>0.01</mass>
            <inertia>
              <ixx>1e-05</ixx>
              <ixy>0</ixy>
              <ixz>0</ixz>
              <iyy>1e-05</iyy>
              <iyz>0</iyz>
              <izz>1e-05</izz>
            </inertia>
            <pose>0 0 0 0 -0 0</pose>
          </inertial>
          <visual name='tilt_viz'>
            <pose>0 0 -0.005 0 -0 0</pose>
            <geometry>
              <mesh>
                <scale>0.001 0.001 0.001</scale>
                <uri>model://gimbal_small_2d/meshes/tilt.dae</uri>
              </mesh>
            </geometry>
            <material>
              <script>
                <uri>file://media/materials/scripts/gazebo.material</uri>
                <name>Gazebo/Grey</name>
              </script>
            </material>
          </visual>
          <collision name='tilt_col'>
            <pose>0 0 -0.005 0 -0 0</pose>
            <geometry>
              <mesh>
                <scale>0.001 0.001 0.001</scale>
                <uri>model://gimbal_small_2d/meshes/tilt.dae</uri>
              </mesh>
            </geometry>
            <max_contacts>10</max_contacts>
            <surface>
              <contact>
                <ode/>
              </contact>
              <bounce/>
              <friction>
                <torsional>
                  <ode/>
                </torsional>
                <ode/>
              </friction>
            </surface>
          </collision>
          <visual name='camera_viz'>
            <pose>0 0 0.02 0 -0 0</pose>
            <geometry>
              <cylinder>
                <radius>0.025</radius>
                <length>0.05</length>
              </cylinder>
            </geometry>
            <material>
              <script>
                <uri>file://media/materials/scripts/gazebo.material</uri>
                <name>Gazebo/Grey</name>
              </script>
            </material>
          </visual>
          <collision name='camera_col'>
            <pose>0 0 0.02 0 -0 0</pose>
            <geometry>
              <cylinder>
                <radius>0.025</radius>
                <length>0.05</length>
              </cylinder>
            </geometry>
            <max_contacts>10</max_contacts>
            <surface>
              <contact>
                <ode/>
              </contact>
              <bounce/>
              <friction>
                <torsional>
                  <ode/>
                </torsional>
                <ode/>
              </friction>
            </surface>
          </collision>
          <sensor name='camera' type='camera'>
            <pose>0 0 0 -1.57 -1.57 0</pose>
            <camera>
              <horizontal_fov>2</horizontal_fov>
              <image>
                <width>640</width>
                <height>480</height>
              </image>
              <clip>
                <near>0.05</near>
                <far>15000</far>
              </clip>
            </camera>
            <always_on>1</always_on>
            <update_rate>10</update_rate>
            <visualize>1</visualize>
          </sensor>
          <pose>0 -0.01 0.07 1.57 -0 1.57</pose>
          <self_collide>0</self_collide>
          <enable_wind>0</enable_wind>
          <kinematic>0</kinematic>
        </link>
        <joint name='gimbal_small_2d::tilt_joint' type='revolute'>
          <parent>gimbal_small_2d::base_link</parent>
          <child>gimbal_small_2d::tilt_link</child>
          <physics>
            <ode>
              <implicit_spring_damper>1</implicit_spring_damper>
              <limit>
                <cfm>0</cfm>
                <erp>0.2</erp>
              </limit>
            </ode>
          </physics>
          <axis>
            <xyz>1 0 -0</xyz>
            <dynamics>
              <damping>0.5</damping>
              <spring_reference>0</spring_reference>
              <spring_stiffness>0</spring_stiffness>
            </dynamics>
            <limit>
              <lower>-0.1</lower>
              <upper>3.14159</upper>
              <effort>10</effort>
              <velocity>-1</velocity>
            </limit>
          </axis>
          <pose>0 0 0.02 0 -0 0</pose>
        </joint>
        <plugin name='gimbal_small_2d' filename='libGimbalSmall2dPlugin.so'>
          <joint>gimbal_small_2d::tilt_joint</joint>
        </plugin>
        <joint name='iris_gimbal_mount' type='revolute'>
          <parent>iris::base_link</parent>
          <child>gimbal_small_2d::base_link</child>
          <axis>
            <limit>
              <lower>0</lower>
              <upper>0</upper>
            </limit>
            <xyz expressed_in='__model__'>0 0 1</xyz>
            <dynamics>
              <spring_reference>0</spring_reference>
              <spring_stiffness>0</spring_stiffness>
            </dynamics>
          </axis>
        </joint>
        <joint name='camera_joint' type='fixed'>
          <parent>base_link</parent>
          <child>camera_link</child>
        </joint>
        <link name='camera_link'>
          <inertial>
            <mass>0.1</mass>
            <inertia>
              <ixx>0.001</ixx>
              <iyy>0.001</iyy>
              <izz>0.001</izz>
              <ixy>0</ixy>
              <ixz>0</ixz>
              <iyz>0</iyz>
            </inertia>
            <pose>0 0 0 0 -0 0</pose>
          </inertial>
          <sensor name='camera' type='camera'>
            <pose>0 0 0.2 0 -0 0</pose>
            <camera>
              <horizontal_fov>1.047</horizontal_fov>
              <image>
                <width>640</width>
                <height>480</height>
                <format>R8G8B8</format>
              </image>
              <clip>
                <near>0.1</near>
                <far>100</far>
              </clip>
            </camera>
            <update_rate>30</update_rate>
            <visualize>1</visualize>
          </sensor>
          <self_collide>0</self_collide>
          <enable_wind>0</enable_wind>
          <kinematic>0</kinematic>
        </link>
        <plugin name='rotor_0_blade_1' filename='libLiftDragPlugin.so'>
          <a0>0.1</a0>
          <alpha_stall>1.4</alpha_stall>
          <cla>0.2500</cla>
          <cda>0.10</cda>
          <cma>0.00</cma>
          <cla_stall>-0.025</cla_stall>
          <cda_stall>0.0</cda_stall>
          <cma_stall>0.0</cma_stall>
          <area>0.2</area>
          <air_density>1.2041</air_density>
          <cp>0.084 0 0</cp>
          <forward>0 1 0</forward>
          <upward>0 0 1</upward>
          <link_name>iris::rotor_0</link_name>
        </plugin>
        <plugin name='rotor_0_blade_2' filename='libLiftDragPlugin.so'>
          <a0>0.1</a0>
          <alpha_stall>1.4</alpha_stall>
          <cla>0.2500</cla>
          <cda>0.10</cda>
          <cma>0.00</cma>
          <cla_stall>-0.025</cla_stall>
          <cda_stall>0.0</cda_stall>
          <cma_stall>0.0</cma_stall>
          <area>0.2</area>
          <air_density>1.2041</air_density>
          <cp>-0.084 0 0</cp>
          <forward>0 -1 0</forward>
          <upward>0 0 1</upward>
          <link_name>iris::rotor_0</link_name>
        </plugin>
        <plugin name='rotor_1_blade_1' filename='libLiftDragPlugin.so'>
          <a0>0.1</a0>
          <alpha_stall>1.4</alpha_stall>
          <cla>0.2500</cla>
          <cda>0.10</cda>
          <cma>0.00</cma>
          <cla_stall>-0.025</cla_stall>
          <cda_stall>0.0</cda_stall>
          <cma_stall>0.0</cma_stall>
          <area>0.2</area>
          <air_density>1.2041</air_density>
          <cp>0.084 0 0</cp>
          <forward>0 1 0</forward>
          <upward>0 0 1</upward>
          <link_name>iris::rotor_1</link_name>
        </plugin>
        <plugin name='rotor_1_blade_2' filename='libLiftDragPlugin.so'>
          <a0>0.1</a0>
          <alpha_stall>1.4</alpha_stall>
          <cla>0.2500</cla>
          <cda>0.10</cda>
          <cma>0.00</cma>
          <cla_stall>-0.025</cla_stall>
          <cda_stall>0.0</cda_stall>
          <cma_stall>0.0</cma_stall>
          <area>0.2</area>
          <air_density>1.2041</air_density>
          <cp>-0.084 0 0</cp>
          <forward>0 -1 0</forward>
          <upward>0 0 1</upward>
          <link_name>iris::rotor_1</link_name>
        </plugin>
        <plugin name='rotor_2_blade_1' filename='libLiftDragPlugin.so'>
          <a0>0.1</a0>
          <alpha_stall>1.4</alpha_stall>
          <cla>0.2500</cla>
          <cda>0.10</cda>
          <cma>0.00</cma>
          <cla_stall>-0.025</cla_stall>
          <cda_stall>0.0</cda_stall>
          <cma_stall>0.0</cma_stall>
          <area>0.2</area>
          <air_density>1.2041</air_density>
          <cp>0.084 0 0</cp>
          <forward>0 -1 0</forward>
          <upward>0 0 1</upward>
          <link_name>iris::rotor_2</link_name>
        </plugin>
        <plugin name='rotor_2_blade_2' filename='libLiftDragPlugin.so'>
          <a0>0.1</a0>
          <alpha_stall>1.4</alpha_stall>
          <cla>0.2500</cla>
          <cda>0.10</cda>
          <cma>0.00</cma>
          <cla_stall>-0.025</cla_stall>
          <cda_stall>0.0</cda_stall>
          <cma_stall>0.0</cma_stall>
          <area>0.2</area>
          <air_density>1.2041</air_density>
          <cp>-0.084 0 0</cp>
          <forward>0 1 0</forward>
          <upward>0 0 1</upward>
          <link_name>iris::rotor_2</link_name>
        </plugin>
        <plugin name='rotor_3_blade_1' filename='libLiftDragPlugin.so'>
          <a0>0.1</a0>
          <alpha_stall>1.4</alpha_stall>
          <cla>0.2500</cla>
          <cda>0.10</cda>
          <cma>0.00</cma>
          <cla_stall>-0.025</cla_stall>
          <cda_stall>0.0</cda_stall>
          <cma_stall>0.0</cma_stall>
          <area>0.2</area>
          <air_density>1.2041</air_density>
          <cp>0.084 0 0</cp>
          <forward>0 -1 0</forward>
          <upward>0 0 1</upward>
          <link_name>iris::rotor_3</link_name>
        </plugin>
        <plugin name='rotor_3_blade_2' filename='libLiftDragPlugin.so'>
          <a0>0.1</a0>
          <alpha_stall>1.4</alpha_stall>
          <cla>0.2500</cla>
          <cda>0.10</cda>
          <cma>0.00</cma>
          <cla_stall>-0.025</cla_stall>
          <cda_stall>0.0</cda_stall>
          <cma_stall>0.0</cma_stall>
          <area>0.2</area>
          <air_density>1.2041</air_density>
          <cp>-0.084 0 0</cp>
          <forward>0 1 0</forward>
          <upward>0 0 1</upward>
          <link_name>iris::rotor_3</link_name>
        </plugin>
        <plugin name='rotors_simulation' filename='libgazebo_motor_model.so'>
          <robotNamespace>iris</robotNamespace>
          <motorNumber>4</motorNumber>
          <turningDirection>1 -1 1 -1</turningDirection>
        </plugin>
        <plugin name='arducopter_plugin' filename='libArduCopterPlugin.so'>
          <imuName>iris_demo::iris::iris/imu_link::imu_sensor</imuName>
          <connectionTimeoutMaxCount>5</connectionTimeoutMaxCount>
          <rotor id='0'>
            <vel_p_gain>0.01</vel_p_gain>
            <vel_i_gain>0</vel_i_gain>
            <vel_d_gain>0</vel_d_gain>
            <vel_i_max>0</vel_i_max>
            <vel_i_min>0</vel_i_min>
            <vel_cmd_max>2.0</vel_cmd_max>
            <vel_cmd_min>-2.0</vel_cmd_min>
            <jointName>iris::rotor_0_joint</jointName>
            <turningDirection>ccw</turningDirection>
            <rotorVelocitySlowdownSim>1</rotorVelocitySlowdownSim>
          </rotor>
          <rotor id='1'>
            <vel_p_gain>0.01</vel_p_gain>
            <vel_i_gain>0</vel_i_gain>
            <vel_d_gain>0</vel_d_gain>
            <vel_i_max>0</vel_i_max>
            <vel_i_min>0</vel_i_min>
            <vel_cmd_max>2.0</vel_cmd_max>
            <vel_cmd_min>-2.0</vel_cmd_min>
            <jointName>iris::rotor_1_joint</jointName>
            <turningDirection>ccw</turningDirection>
            <rotorVelocitySlowdownSim>1</rotorVelocitySlowdownSim>
          </rotor>
          <rotor id='2'>
            <vel_p_gain>0.01</vel_p_gain>
            <vel_i_gain>0</vel_i_gain>
            <vel_d_gain>0</vel_d_gain>
            <vel_i_max>0</vel_i_max>
            <vel_i_min>0</vel_i_min>
            <vel_cmd_max>2.0</vel_cmd_max>
            <vel_cmd_min>-2.0</vel_cmd_min>
            <jointName>iris::rotor_2_joint</jointName>
            <turningDirection>cw</turningDirection>
            <rotorVelocitySlowdownSim>1</rotorVelocitySlowdownSim>
          </rotor>
          <rotor id='3'>
            <vel_p_gain>0.01</vel_p_gain>
            <vel_i_gain>0</vel_i_gain>
            <vel_d_gain>0</vel_d_gain>
            <vel_i_max>0</vel_i_max>
            <vel_i_min>0</vel_i_min>
            <vel_cmd_max>2.0</vel_cmd_max>
            <vel_cmd_min>-2.0</vel_cmd_min>
            <jointName>iris::rotor_3_joint</jointName>
            <turningDirection>cw</turningDirection>
            <rotorVelocitySlowdownSim>1</rotorVelocitySlowdownSim>
          </rotor>
        </plugin>
        <plugin name='camera_controller' filename='libgazebo_ros_camera.so'>
          <always_on>1</always_on>
          <update_rate>30</update_rate>
          <camera_name>iris_camera</camera_name>
          <image_topic_name>/camera/image_raw</image_topic_name>
          <camera_info_topic_name>/camera/camera_info</camera_info_topic_name>
        </plugin>
        <pose>-1.71681 -0.000122 0 0 -0 0</pose>
      </model>
      <static>0</static>
      <allow_auto_disable>1</allow_auto_disable>
      <pose>1.3044 -0.674477 0 0 -0 0</pose>
    </model>
    <state world_name='default'>
      <sim_time>76 847000000</sim_time>
      <real_time>85 202875017</real_time>
      <wall_time>1735949770 313265502</wall_time>
      <iterations>76847</iterations>
      <model name='drone'>
        <pose>1.3044 -0.674477 0 0 -0 0</pose>
        <scale>1 1 1</scale>
        <model name='house'>
          <pose>3.02121 -0.674355 0 0 -0 0</pose>
          <scale>1 1 1</scale>
          <link name='Wall_0'>
            <pose>-3.00879 -0.946855 0 0 0 -1.5708</pose>
            <velocity>0 0 0 0 -0 0</velocity>
            <acceleration>0 0 0 0 -0 0</acceleration>
            <wrench>0 0 0 0 -0 0</wrench>
          </link>
          <link name='Wall_1'>
            <pose>-0.95879 -2.37186 0 0 -0 0</pose>
            <velocity>0 0 0 0 -0 0</velocity>
            <acceleration>0 0 0 0 -0 0</acceleration>
            <wrench>0 0 0 0 -0 0</wrench>
          </link>
          <link name='Wall_10'>
            <pose>2.76621 -2.37186 0 0 -0 0</pose>
            <velocity>0 0 0 0 -0 0</velocity>
            <acceleration>0 0 0 0 -0 0</acceleration>
            <wrench>0 0 0 0 -0 0</wrench>
          </link>
          <link name='Wall_11'>
            <pose>4.44621 -2.37186 0 0 -0 0</pose>
            <velocity>0 0 0 0 -0 0</velocity>
            <acceleration>0 0 0 0 -0 0</acceleration>
            <wrench>0 0 0 0 -0 0</wrench>
          </link>
          <link name='Wall_12'>
            <pose>6.75121 -2.37186 0 0 -0 0</pose>
            <velocity>0 0 0 0 -0 0</velocity>
            <acceleration>0 0 0 0 -0 0</acceleration>
            <wrench>0 0 0 0 -0 0</wrench>
          </link>
          <link name='Wall_13'>
            <pose>9.05121 -1.32186 0 0 -0 1.5708</pose>
            <velocity>0 0 0 0 -0 0</velocity>
            <acceleration>0 0 0 0 -0 0</acceleration>
            <wrench>0 0 0 0 -0 0</wrench>
          </link>
          <link name='Wall_15'>
            <pose>6.74121 0.478145 0 0 -0 0</pose>
            <velocity>0 0 0 0 -0 0</velocity>
            <acceleration>0 0 0 0 -0 0</acceleration>
            <wrench>0 0 0 0 -0 0</wrench>
          </link>
          <link name='Wall_2'>
            <pose>1.09121 -1.94686 0 0 -0 1.5708</pose>
            <velocity>0 0 0 0 -0 0</velocity>
            <acceleration>0 0 0 0 -0 0</acceleration>
            <wrench>0 0 0 0 -0 0</wrench>
          </link>
          <link name='Wall_4'>
            <pose>-0.95879 0.478145 0 0 -0 0</pose>
            <velocity>0 0 0 0 -0 0</velocity>
            <acceleration>0 0 0 0 -0 0</acceleration>
            <wrench>0 0 0 0 -0 0</wrench>
          </link>
          <link name='Wall_5'>
            <pose>1.09121 0.053145 0 0 0 -1.5708</pose>
            <velocity>0 0 0 0 -0 0</velocity>
            <acceleration>0 0 0 0 -0 0</acceleration>
            <wrench>0 0 0 0 -0 0</wrench>
          </link>
          <link name='Wall_7'>
            <pose>2.76621 0.478145 0 0 -0 0</pose>
            <velocity>0 0 0 0 -0 0</velocity>
            <acceleration>0 0 0 0 -0 0</acceleration>
            <wrench>0 0 0 0 -0 0</wrench>
          </link>
          <link name='Wall_8'>
            <pose>4.44121 -0.571855 0 0 0 -1.5708</pose>
            <velocity>0 0 0 0 -0 0</velocity>
            <acceleration>0 0 0 0 -0 0</acceleration>
            <wrench>0 0 0 0 -0 0</wrench>
          </link>
        </model>
        <model name='iris_demo'>
          <pose>-0.41241 -0.674599 0 0 -0 0</pose>
          <scale>1 1 1</scale>
          <link name='camera_link'>
            <pose>-0.41241 -0.674599 -18875.4 0 -0 0</pose>
            <velocity>0 0 -608.237 0 -0 0</velocity>
            <acceleration>0 0 -9.8 0 -0 0</acceleration>
            <wrench>0 0 -0.98 0 -0 0</wrench>
          </link>
          <link name='gimbal_small_2d::base_link'>
            <pose>-0.412412 -0.684069 0.069595 1.57 0.002115 1.56999</pose>
            <velocity>2e-06 1.3e-05 5e-05 -0.000178 2.8e-05 0.000121</velocity>
            <acceleration>-0 -1e-06 -0 4e-06 0.000539 0.255295</acceleration>
            <wrench>-0 -0 -0 0 -0 0</wrench>
          </link>
          <link name='gimbal_small_2d::tilt_link'>
            <pose>-0.392428 -0.684042 0.089611 3.14079 0.002115 1.56999</pose>
            <velocity>3e-06 1.9e-05 5e-05 -0.000178 3e-05 0.000121</velocity>
            <acceleration>4e-06 0.0051 -1.1e-05 4e-06 0.000536 0.255295</acceleration>
            <wrench>0 5.1e-05 -0 0 -0 0</wrench>
          </link>
          <link name='iris::base_link'>
            <pose>-0.412411 -0.673804 0.194497 -0.002116 2e-06 -8e-06</pose>
            <velocity>5e-06 3.5e-05 4.8e-05 -0.000178 2.8e-05 0</velocity>
            <acceleration>-0 -1e-06 -0 7e-06 -2e-06 -0</acceleration>
            <wrench>-0 -2e-06 -0 0 -0 0</wrench>
          </link>
          <link name='iris::iris/ground_truth/odometry_sensorgt_link'>
            <pose>-0.412411 -0.673804 0.194497 -0.002115 2e-06 -8e-06</pose>
            <velocity>5e-06 3.5e-05 4.8e-05 -0.000178 2.7e-05 -0.000124</velocity>
            <acceleration>-0 -2e-06 -0 3e-06 -0.000506 -0.238699</acceleration>
            <wrench>-0 -0 -0 0 -0 0</wrench>
          </link>
          <link name='iris::iris/imu_link'>
            <pose>-0.412411 -0.673804 0.194497 -0.002115 2e-06 -8e-06</pose>
            <velocity>5e-06 3.5e-05 4.8e-05 -0.000178 2.7e-05 -0.000124</velocity>
            <acceleration>-0 -2e-06 -0 3e-06 -0.000506 -0.238868</acceleration>
            <wrench>-0 -0 -0 0 -0 0</wrench>
          </link>
          <link name='iris::rotor_0'>
            <pose>-0.282413 -0.893756 0.217962 -0.002115 2e-06 1e-06</pose>
            <velocity>6e-06 3.9e-05 8.4e-05 -0.000178 2.8e-05 -5e-06</velocity>
            <acceleration>-0 -2e-06 -1e-06 3e-06 -1e-06 -2.5e-05</acceleration>
            <wrench>-0 -0 -0 0 -0 0</wrench>
          </link>
          <link name='iris::rotor_1'>
            <pose>-0.54241 -0.473755 0.217074 -0.002115 2e-06 -5.5e-05</pose>
            <velocity>6e-06 3.9e-05 1.6e-05 -0.000178 2.8e-05 -5e-06</velocity>
            <acceleration>-0 -2e-06 0 3e-06 -1e-06 -2.3e-05</acceleration>
            <wrench>-0 -0 0 0 -0 0</wrench>
          </link>
          <link name='iris::rotor_2'>
            <pose>-0.28241 -0.453757 0.217031 -0.002115 2e-06 -5e-06</pose>
            <velocity>6e-06 3.9e-05 5e-06 -0.000178 2.8e-05 -5e-06</velocity>
            <acceleration>-0 -2e-06 1e-06 3e-06 -1e-06 -2.3e-05</acceleration>
            <wrench>-0 -0 0 0 -0 0</wrench>
          </link>
          <link name='iris::rotor_3'>
            <pose>-0.542413 -0.873754 0.21792 -0.002115 2e-06 -5.9e-05</pose>
            <velocity>6e-06 3.9e-05 8.8e-05 -0.000178 2.8e-05 -6e-06</velocity>
            <acceleration>-0 -2e-06 -1e-06 3e-06 -1e-06 -2.3e-05</acceleration>
            <wrench>-0 -0 -0 0 -0 0</wrench>
          </link>
        </model>
      </model>
      <model name='ground_plane'>
        <pose>0 0 0 0 -0 0</pose>
        <scale>1 1 1</scale>
        <link name='link'>
          <pose>0 0 0 0 -0 0</pose>
          <velocity>0 0 0 0 -0 0</velocity>
          <acceleration>0 0 0 0 -0 0</acceleration>
          <wrench>0 0 0 0 -0 0</wrench>
        </link>
      </model>
      <light name='sun'>
        <pose>0 0 10 0 -0 0</pose>
      </light>
    </state>
    <gui fullscreen='0'>
      <camera name='user_camera'>
        <pose>0 0 7.34847 3.14159 1.57079 3.14159</pose>
        <view_controller>orbit</view_controller>
        <projection_type>perspective</projection_type>
      </camera>
    </gui>
  </world>
</sdf>
